Traceback (most recent call last):
  File "/Users/ranit/anaconda3/envs/gbi-python-env/lib/python3.13/site-packages/jupyter_core/utils/__init__.py", line 154, in wrapped
    asyncio.get_running_loop()
    ~~~~~~~~~~~~~~~~~~~~~~~~^^
RuntimeError: no running event loop

During handling of the above exception, another exception occurred:

Traceback (most recent call last):
  File "/Users/ranit/anaconda3/envs/gbi-python-env/lib/python3.13/site-packages/jupyter_cache/executors/utils.py", line 58, in single_nb_execution
    executenb(
    ~~~~~~~~~^
        nb,
        ^^^
    ...<4 lines>...
        **kwargs,
        ^^^^^^^^^
    )
    ^
  File "/Users/ranit/anaconda3/envs/gbi-python-env/lib/python3.13/site-packages/nbclient/client.py", line 1319, in execute
    return NotebookClient(nb=nb, resources=resources, km=km, **kwargs).execute()
           ~~~~~~~~~~~~~~~~~~~~~~~~~~~~~~~~~~~~~~~~~~~~~~~~~~~~~~~~~~~~~~~~~~~^^
  File "/Users/ranit/anaconda3/envs/gbi-python-env/lib/python3.13/site-packages/jupyter_core/utils/__init__.py", line 158, in wrapped
    return loop.run_until_complete(inner)
           ~~~~~~~~~~~~~~~~~~~~~~~^^^^^^^
  File "/Users/ranit/anaconda3/envs/gbi-python-env/lib/python3.13/asyncio/base_events.py", line 721, in run_until_complete
    return future.result()
           ~~~~~~~~~~~~~^^
  File "/Users/ranit/anaconda3/envs/gbi-python-env/lib/python3.13/site-packages/nbclient/client.py", line 709, in async_execute
    await self.async_execute_cell(
        cell, index, execution_count=self.code_cells_executed + 1
    )
  File "/Users/ranit/anaconda3/envs/gbi-python-env/lib/python3.13/site-packages/nbclient/client.py", line 1062, in async_execute_cell
    await self._check_raise_for_error(cell, cell_index, exec_reply)
  File "/Users/ranit/anaconda3/envs/gbi-python-env/lib/python3.13/site-packages/nbclient/client.py", line 918, in _check_raise_for_error
    raise CellExecutionError.from_cell_and_msg(cell, exec_reply_content)
nbclient.exceptions.CellExecutionError: An error occurred while executing the following cell:
------------------
from bioimageio.core import load_resource_description
from bioimageio.core.prediction import predict_with_numpy_input
import numpy as np
import tifffile
import napari

# Load model
rdf = load_resource_description("https://bioimage.io/model-zoo/xyz")

# Load image
img = tifffile.imread("your_image.tif")

# Run prediction
pred = predict_with_numpy_input(rdf, img)

# View in Napari
viewer = napari.Viewer()
viewer.add_image(img, name="Original")
viewer.add_image(pred["predictions"], name="Prediction")
------------------


[31m---------------------------------------------------------------------------[39m
[31mModuleNotFoundError[39m                       Traceback (most recent call last)
[36mCell[39m[36m [39m[32mIn[1][39m[32m, line 1[39m
[32m----> [39m[32m1[39m [38;5;28;01mfrom[39;00m[38;5;250m [39m[34;01mbioimageio[39;00m[34;01m.[39;00m[34;01mcore[39;00m[38;5;250m [39m[38;5;28;01mimport[39;00m load_resource_description
[32m      2[39m [38;5;28;01mfrom[39;00m[38;5;250m [39m[34;01mbioimageio[39;00m[34;01m.[39;00m[34;01mcore[39;00m[34;01m.[39;00m[34;01mprediction[39;00m[38;5;250m [39m[38;5;28;01mimport[39;00m predict_with_numpy_input
[32m      3[39m [38;5;28;01mimport[39;00m[38;5;250m [39m[34;01mnumpy[39;00m[38;5;250m [39m[38;5;28;01mas[39;00m[38;5;250m [39m[34;01mnp[39;00m

[31mModuleNotFoundError[39m: No module named 'bioimageio'

