Traceback (most recent call last):
  File "/Users/ranit/anaconda3/lib/python3.11/site-packages/jupyter_cache/executors/utils.py", line 58, in single_nb_execution
    executenb(
  File "/Users/ranit/anaconda3/lib/python3.11/site-packages/nbclient/client.py", line 1204, in execute
    return NotebookClient(nb=nb, resources=resources, km=km, **kwargs).execute()
           ^^^^^^^^^^^^^^^^^^^^^^^^^^^^^^^^^^^^^^^^^^^^^^^^^^^^^^^^^^^^^^^^^^^^^
  File "/Users/ranit/anaconda3/lib/python3.11/site-packages/nbclient/util.py", line 84, in wrapped
    return just_run(coro(*args, **kwargs))
           ^^^^^^^^^^^^^^^^^^^^^^^^^^^^^^^
  File "/Users/ranit/anaconda3/lib/python3.11/site-packages/nbclient/util.py", line 62, in just_run
    return loop.run_until_complete(coro)
           ^^^^^^^^^^^^^^^^^^^^^^^^^^^^^
  File "/Users/ranit/anaconda3/lib/python3.11/asyncio/base_events.py", line 653, in run_until_complete
    return future.result()
           ^^^^^^^^^^^^^^^
  File "/Users/ranit/anaconda3/lib/python3.11/site-packages/nbclient/client.py", line 663, in async_execute
    await self.async_execute_cell(
  File "/Users/ranit/anaconda3/lib/python3.11/site-packages/nbclient/client.py", line 965, in async_execute_cell
    await self._check_raise_for_error(cell, cell_index, exec_reply)
  File "/Users/ranit/anaconda3/lib/python3.11/site-packages/nbclient/client.py", line 862, in _check_raise_for_error
    raise CellExecutionError.from_cell_and_msg(cell, exec_reply_content)
nbclient.exceptions.CellExecutionError: An error occurred while executing the following cell:
------------------
from bioimageio.core import load_resource_description
from bioimageio.core.prediction import predict_with_numpy_input
import numpy as np
import tifffile
import napari

# Load model
rdf = load_resource_description("https://bioimage.io/model-zoo/xyz")

# Load image
img = tifffile.imread("your_image.tif")

# Run prediction
pred = predict_with_numpy_input(rdf, img)

# View in Napari
viewer = napari.Viewer()
viewer.add_image(img, name="Original")
viewer.add_image(pred["predictions"], name="Prediction")
------------------

[0;31m---------------------------------------------------------------------------[0m
[0;31mModuleNotFoundError[0m                       Traceback (most recent call last)
Cell [0;32mIn[1], line 1[0m
[0;32m----> 1[0m [38;5;28;01mfrom[39;00m[38;5;250m [39m[38;5;21;01mbioimageio[39;00m[38;5;21;01m.[39;00m[38;5;21;01mcore[39;00m[38;5;250m [39m[38;5;28;01mimport[39;00m load_resource_description
[1;32m      2[0m [38;5;28;01mfrom[39;00m[38;5;250m [39m[38;5;21;01mbioimageio[39;00m[38;5;21;01m.[39;00m[38;5;21;01mcore[39;00m[38;5;21;01m.[39;00m[38;5;21;01mprediction[39;00m[38;5;250m [39m[38;5;28;01mimport[39;00m predict_with_numpy_input
[1;32m      3[0m [38;5;28;01mimport[39;00m[38;5;250m [39m[38;5;21;01mnumpy[39;00m[38;5;250m [39m[38;5;28;01mas[39;00m[38;5;250m [39m[38;5;21;01mnp[39;00m

[0;31mModuleNotFoundError[0m: No module named 'bioimageio'
ModuleNotFoundError: No module named 'bioimageio'

